
FAIL returning early from an iteration doesn't crash promise_test: Unhandled rejection with value: object "NotSupportedError: The operation is not supported."
FAIL @@asyncIterator: full iteration works promise_test: Unhandled rejection with value: object "NotSupportedError: The operation is not supported."
FAIL entries: full iteration works promise_test: Unhandled rejection with value: object "NotSupportedError: The operation is not supported."
FAIL values: full iteration works promise_test: Unhandled rejection with value: object "NotSupportedError: The operation is not supported."
FAIL keys: full iteration works promise_test: Unhandled rejection with value: object "NotSupportedError: The operation is not supported."
FAIL iteration while iterator gets garbage collected promise_test: Unhandled rejection with value: object "NotSupportedError: The operation is not supported."

